Workbook

Sheet IP Input Sheet
A1: AES-220 | IP Address Input Sheet | Enter all IP values here
A2: Fill in the IP/Subnet for each component. All firewall rule tabs will auto-populate.
A3: # | B3: Component / Service | C3: Named Range Key | D3: AZ1 IP / Subnet | E3: AZ2 IP / Subnet | F3: AZ3 IP / Subnet
A4: 🔷 FLEET COMPONENTS (NSX Overlay Segment)
A5: F1 | B5: VCF Operations Fleet Manager | C5: FLEET_MGR | D5: 10.5.25.86 | E5: 10.5.25.86
A6: F2 | B6: VCF Operations (VCFO) | C6: VCFO | D6: 10.5.25.64/26
A7: F3 | B7: VCF Automation (VCFA) | C7: VCFA | D7: 10.5.25.64/26
A8: F4 | B8: VCF Operations for Logs (VOL) | C8: VOL | D8: 10.5.25.64/26
A9: F5 | B9: VCF Operations for Networks (VON) | C9: VON | D9: 10.5.25.64/26
A10: F6 | B10: Identity Broker (VIDB) | C10: VIDB | D10: 10.3.118.0/24 | E10: 10.5.59.0/24
A11: F7 | B11: Fleet Overlay Subnet (overall) | C11: FLEET_SUBNET | D11: 10.5.25.64/26 | E11: 10.5.25.64/26
A12: 🔷 MANAGEMENT DOMAIN COMPONENTS (VLAN 2600 — per AZ)
A13: M1 | B13: vCenter Server | C13: VCENTER | D13: 10.3.118.18 | E13: 10.5.59.4
A14: M2 | B14: NSX Manager (Local) | C14: NSX_MGR | D14: 10.3.118.0/24 | E14: 10.5.59.0/24
A15: M3 | B15: NSX Global Manager | C15: NSX_GM | D15: 10.3.118.0/24 | E15: 10.5.59.0/24
A16: M4 | B16: SDDC Manager | C16: SDDC_MGR | D16: 10.3.118.30 | E16: 10.5.59.30
A17: M5 | B17: VCF Operations Collector | C17: VCFO_COLL | D17: 10.3.118.35 | E17: 10.5.59.35
A18: M6 | B18: ESXi Mgmt Subnet — Mgmt Domain | C18: ESXI_MGMT_MD | D18: 10.3.118.0/24 | E18: 10.5.59.0/24 | F18: 10.5.58.0/24
A19: M7 | B19: VCF OPS for Network Collector | C19: VON_COLL | D19: 10.3.118.101
A20: M8 | B20: VMware Live Recovery (VLR) Appliance — sfoMGMT-1-1-vlsr1.test.net | C20: VLR_MGMT | D20: 192.168.188.1
A21: 🔷 EDGE CLUSTER UPLINKS (per AZ — Edge VM IPs | ToR IPs )
A22: EU1 | B22: Edge 1 — Uplink 1 (VLAN 2606 — Rack 1) | C22: EDGE1_UPL1 | D22: 10.3.111.101 | E22: 10.3.111.231
A23: EU2 | B23: Edge 1 — Uplink 2 (VLAN 2607 — Rack 1) | C23: EDGE1_UPL2 | D23: 10.3.111.121 | E23: 10.3.111.241
A24: EU3 | B24: Edge 2 — Uplink 1 (VLAN 2606 — Rack 1) | C24: EDGE2_UPL1 | D24: 10.3.111.102 | E24: 10.3.111.232
A25: EU4 | B25: Edge 2 — Uplink 2 (VLAN 2607 — Rack 1) | C25: EDGE2_UPL2 | D25: 10.3.111.122 | E25: 10.3.111.242
A26: EU5 | B26: Edge 3 — Uplink 1 (VLAN 2608 — Rack 2) | C26: EDGE3_UPL1 | D26: 10.3.111.133 | E26: 10.5.25.13
A27: EU6 | B27: Edge 3 — Uplink 2 (VLAN 2609 — Rack 2) | C27: EDGE3_UPL2 | D27: 10.3.111.153 | E27: 10.5.25.23
A28: EU7 | B28: Edge 4 — Uplink 1 (VLAN 2608 — Rack 2) | C28: EDGE4_UPL1 | D28: 10.3.111.134 | E28: 10.5.25.14
A29: EU8 | B29: Edge 4 — Uplink 2 (VLAN 2609 — Rack 2) | C29: EDGE4_UPL2 | D29: 10.3.111.154 | E29: 10.5.25.24
A30: EU9 | B30: Edge TEP Subnet (VLAN 2603 — intra-AZ HA + GENEVE) | C30: EDGE_TEP | D30: 10.5.236.0/24 | E30: 10.5.248.0/24
A31: EU10 | B31: Remote TEP Subnet (VLAN 2605 — cross-AZ GENEVE) | C31: EDGE_RTEP | D31: 10.5.22.0/24 | E31: 10.5.24.0/24
A32: EU11 | B32: ToR BGP Peer — Rack 1 Uplink 1 (VLAN 2606) | C32: TOR_R1_UPL1 | D32: 10.3.111.97 | E32: 10.3.111.225
A33: EU12 | B33: ToR BGP Peer — Rack 1 Uplink 2 (VLAN 2607) | C33: TOR_R1_UPL2 | D33: 10.3.111.113 | E33: 10.3.111.241
A34: EU13 | B34: ToR BGP Peer — Rack 2 Uplink 1 (VLAN 2608) | C34: TOR_R2_UPL1 | D34: 10.3.111.129 | E34: 10.5.25.1
A35: EU14 | B35: ToR BGP Peer — Rack 2 Uplink 2 (VLAN 2609) | C35: TOR_R2_UPL2
A36: 🔷 EDGE NODE DETAIL (per-node individual IPs — for NSX deployment config, not firewall rules)
A37: EN1_UPL1 | B37: Edge Node 1 — Uplink 1 IP (phxvq1cinflne01.phx.aexp.com) | C37: EN1_UPL1_IP
A38: EN1_UPL2 | B38: Edge Node 1 — Uplink 2 IP (phxvq1cinflne01.phx.aexp.com) | C38: EN1_UPL2_IP
A39: EN1_RTEP | B39: Edge Node 1 — RTEP IP (phxvq1cinflne01.phx.aexp.com) | C39: EN1_RTEP_IP
A40: EN1_ETEP | B40: Edge Node 1 — Edge TEP IP (phxvq1cinflne01.phx.aexp.com) | C40: EN1_ETEP_IP
...

Sheet Fleet → Mgmt+WLD
A1: AES-220 | Firewall Rules | Fleet → Management Domain & WLD ESXi Hosts
A2: Source IP and Destination IP auto-populate from 'IP Input Sheet'. Fill in IPs there first.
A3: # | B3: Rule Name | C3: Source Component | D3: Source IP / Subnet | E3: Destination Component | F3: Destination IP / Subnet | G3: Port | H3: Protocol | I3: Service / Application | J3: Action | K3: Firewall Type | L3: Flow Direction | M3: Notes
A4: FM-01 | B4: Fleet Mgr → SDDC Mgmt | C4: VCF Operations Fleet Manager | D4: =IFERROR(IF('IP Input Sheet'!D5<>"",'IP Input Sheet'!D5,IF('IP Input Sheet'!E5<>"",'IP Input Sheet'!E5,'IP Input Sheet'!F5)),"[Enter IP]") | E4: SDDC Manager | F4: =IFERROR(IF('IP Input Sheet'!D16<>"",'IP Input Sheet'!D16,IF('IP Input Sheet'!E16<>"",'IP Input Sheet'!E16,'IP Input Sheet'!F16)),"[Enter IP]") | G4: 443 | H4: TCP | I4: Lifecycle Management | J4: Allow | K4: Gateway FW | L4: Outbound | M4: Ticket req #3 — Fleet→Mgmt
A5: FM-02 | B5: Fleet Mgr → VCF Operations | C5: VCF Operations Fleet Manager | D5: =IFERROR(IF('IP Input Sheet'!D5<>"",'IP Input Sheet'!D5,IF('IP Input Sheet'!E5<>"",'IP Input Sheet'!E5,'IP Input Sheet'!F5)),"[Enter IP]") | E5: VCF Operations (VCFO) | F5: =IFERROR(IF('IP Input Sheet'!D6<>"",'IP Input Sheet'!D6,IF('IP Input Sheet'!E6<>"",'IP Input Sheet'!E6,'IP Input Sheet'!F6)),"[Enter IP]") | G5: 443 | H5: TCP | I5: VCF Ops collector metrics | J5: Allow | K5: Gateway FW | L5: Outbound | M5: Bidirectional
A6: FM-03 | B6: Fleet Mgr → vCenter | C6: VCF Operations Fleet Manager | D6: =IFERROR(IF('IP Input Sheet'!D5<>"",'IP Input Sheet'!D5,IF('IP Input Sheet'!E5<>"",'IP Input Sheet'!E5,'IP Input Sheet'!F5)),"[Enter IP]") | E6: vCenter Server | F6: =IFERROR(IF('IP Input Sheet'!D13<>"",'IP Input Sheet'!D13,IF('IP Input Sheet'!E13<>"",'IP Input Sheet'!E13,'IP Input Sheet'!F13)),"[Enter IP]") | G6: 443 | H6: TCP | I6: vCenter config & mgmt tasks | J6: Allow | K6: Gateway FW | L6: Outbound
A7: FM-04 | B7: Fleet Mgr → NSX Manager | C7: VCF Operations Fleet Manager | D7: =IFERROR(IF('IP Input Sheet'!D5<>"",'IP Input Sheet'!D5,IF('IP Input Sheet'!E5<>"",'IP Input Sheet'!E5,'IP Input Sheet'!F5)),"[Enter IP]") | E7: NSX Manager | F7: =IFERROR(IF('IP Input Sheet'!D14<>"",'IP Input Sheet'!D14,IF('IP Input Sheet'!E14<>"",'IP Input Sheet'!E14,'IP Input Sheet'!F14)),"[Enter IP]") | G7: 443 | H7: TCP | I7: NSX networking & security config | J7: Allow | K7: Gateway FW | L7: Outbound
A8: FM-05 | B8: Fleet Mgr → DNS | C8: VCF Operations Fleet Manager | D8: =IFERROR(IF('IP Input Sheet'!D5<>"",'IP Input Sheet'!D5,IF('IP Input Sheet'!E5<>"",'IP Input Sheet'!E5,'IP Input Sheet'!F5)),"[Enter IP]") | E8: DNS Server | F8: ='IP Input Sheet'!D60 | G8: 53 | H8: TCP/UDP | I8: Name resolution | J8: Allow | K8: Gateway FW | L8: Bidirectional | M8: All Fleet+VCF components
A9: FM-06 | B9: Fleet Mgr → NTP | C9: VCF Operations Fleet Manager | D9: =IFERROR(IF('IP Input Sheet'!D5<>"",'IP Input Sheet'!D5,IF('IP Input Sheet'!E5<>"",'IP Input Sheet'!E5,'IP Input Sheet'!F5)),"[Enter IP]") | E9: NTP Server | F9: ='IP Input Sheet'!D61 | G9: 123 | H9: UDP | I9: Time synchronisation | J9: Allow | K9: Gateway FW | L9: Outbound
A10: FM-07 | B10: Fleet Mgr → ESXi (HTTPS) | C10: VCF Operations Fleet Manager | D10: =IFERROR(IF('IP Input Sheet'!D5<>"",'IP Input Sheet'!D5,IF('IP Input Sheet'!E5<>"",'IP Input Sheet'!E5,'IP Input Sheet'!F5)),"[Enter IP]") | E10: ESXi Hosts (WLD) | F10: =IFERROR(IF('IP Input Sheet'!D54<>"",'IP Input Sheet'!D54,IF('IP Input Sheet'!E54<>"",'IP Input Sheet'!E54,'IP Input Sheet'!F54)),"[Enter IP]") | G10: 443 | H10: TCP | I10: Secure web services / APIs | J10: Allow | K10: Gateway FW | L10: Outbound
A11: FM-08 | B11: Fleet Mgr → VCFA (SSH) | C11: VCF Operations Fleet Manager | D11: =IFERROR(IF('IP Input Sheet'!D5<>"",'IP Input Sheet'!D5,IF('IP Input Sheet'!E5<>"",'IP Input Sheet'!E5,'IP Input Sheet'!F5)),"[Enter IP]") | E11: VCF Automation | F11: =IFERROR(IF('IP Input Sheet'!D7<>"",'IP Input Sheet'!D7,IF('IP Input Sheet'!E7<>"",'IP Input Sheet'!E7,'IP Input Sheet'!F7)),"[Enter IP]") | G11: 22 | H11: TCP | I11: SSH lifecycle tasks | J11: Allow | K11: Gateway FW | L11: Outbound | M11: Admin restrict to jump host
A12: FM-09 | B12: Fleet Mgr → VCFA+VIDB (6443) | C12: VCF Operations Fleet Manager | D12: =IFERROR(IF('IP Input Sheet'!D5<>"",'IP Input Sheet'!D5,IF('IP Input Sheet'!E5<>"",'IP Input Sheet'!E5,'IP Input Sheet'!F5)),"[Enter IP]") | E12: Identity Broker & VCF Automation | F12: =IFERROR(IF('IP Input Sheet'!D7<>"",'IP Input Sheet'!D7,IF('IP Input Sheet'!E7<>"",'IP Input Sheet'!E7,'IP Input Sheet'!F7)),"[Enter IP]") | G12: 6443 | H12: TCP | I12: Control Plane API (k8s apiserver) | J12: Allow | K12: Gateway FW | L12: Outbound
A13: FM-10 | B13: Fleet Mgr → VCFA+VIDB (30006) | C13: VCF Operations Fleet Manager | D13: =IFERROR(IF('IP Input Sheet'!D5<>"",'IP Input Sheet'!D5,IF('IP Input Sheet'!E5<>"",'IP Input Sheet'!E5,'IP Input Sheet'!F5)),"[Enter IP]") | E13: Identity Broker & VCF Automation | F13: =IFERROR(IF('IP Input Sheet'!D7<>"",'IP Input Sheet'!D7,IF('IP Input Sheet'!E7<>"",'IP Input Sheet'!E7,'IP Input Sheet'!F7)),"[Enter IP]") | G13: 30006 | H13: TCP | I13: Validates VCFA health pre-LCM | J13: Allow | K13: Gateway FW | L13: Outbound
A14: FM-11 | B14: Fleet Mgr → VCFA+VIDB (30005) | C14: VCF Operations Fleet Manager | D14: =IFERROR(IF('IP Input Sheet'!D5<>"",'IP Input Sheet'!D5,IF('IP Input Sheet'!E5<>"",'IP Input Sheet'!E5,'IP Input Sheet'!F5)),"[Enter IP]") | E14: Identity Broker & VCF Automation | F14: =IFERROR(IF('IP Input Sheet'!D7<>"",'IP Input Sheet'!D7,IF('IP Input Sheet'!E7<>"",'IP Input Sheet'!E7,'IP Input Sheet'!F7)),"[Enter IP]") | G14: 30005 | H14: TCP | I14: API calls to VIDB & VCFA | J14: Allow | K14: Gateway FW | L14: Outbound
A15: FM-12 | B15: Fleet Mgr → VCFA+VIDB (30001) | C15: VCF Operations Fleet Manager | D15: =IFERROR(IF('IP Input Sheet'!D5<>"",'IP Input Sheet'!D5,IF('IP Input Sheet'!E5<>"",'IP Input Sheet'!E5,'IP Input Sheet'!F5)),"[Enter IP]") | E15: Identity Broker & VCF Automation | F15: =IFERROR(IF('IP Input Sheet'!D7<>"",'IP Input Sheet'!D7,IF('IP Input Sheet'!E7<>"",'IP Input Sheet'!E7,'IP Input Sheet'!F7)),"[Enter IP]") | G15: 30001 | H15: TCP | I15: Container images (k8s/VKS) | J15: Allow | K15: Gateway FW | L15: Outbound
A16: FM-13 | B16: Fleet Mgr → VCFA+VIDB (30000) | C16: VCF Operations Fleet Manager | D16: =IFERROR(IF('IP Input Sheet'!D5<>"",'IP Input Sheet'!D5,IF('IP Input Sheet'!E5<>"",'IP Input Sheet'!E5,'IP Input Sheet'!F5)),"[Enter IP]") | E16: Identity Broker & VCF Automation | F16: =IFERROR(IF('IP Input Sheet'!D7<>"",'IP Input Sheet'!D7,IF('IP Input Sheet'!E7<>"",'IP Input Sheet'!E7,'IP Input Sheet'!F7)),"[Enter IP]") | G16: 30000 | H16: TCP | I16: Container images (k8s/VKS) | J16: Allow | K16: Gateway FW | L16: Outbound
A17: FM-14 | B17: Fleet Mgr → VCFA health | C17: VCF Operations Fleet Manager | D17: =IFERROR(IF('IP Input Sheet'!D5<>"",'IP Input Sheet'!D5,IF('IP Input Sheet'!E5<>"",'IP Input Sheet'!E5,'IP Input Sheet'!F5)),"[Enter IP]") | E17: VCF Automation | F17: =IFERROR(IF('IP Input Sheet'!D7<>"",'IP Input Sheet'!D7,IF('IP Input Sheet'!E7<>"",'IP Input Sheet'!E7,'IP Input Sheet'!F7)),"[Enter IP]") | G17: 8008 | H17: TCP | I17: Health check monitoring | J17: Allow | K17: Gateway FW | L17: Outbound
A18: VO-01 | B18: VCF Ops → NTP | C18: VCF Operations (VCFO) | D18: =IFERROR(IF('IP Input Sheet'!D6<>"",'IP Input Sheet'!D6,IF('IP Input Sheet'!E6<>"",'IP Input Sheet'!E6,'IP Input Sheet'!F6)),"[Enter IP]") | E18: NTP Server | F18: ='IP Input Sheet'!D61 | G18: 123 | H18: UDP | I18: Time sync — primary/replica/data nodes | J18: Allow | K18: Gateway FW | L18: Outbound
A19: VO-02 | B19: VCF Ops → DNS | C19: VCF Operations (VCFO) | D19: =IFERROR(IF('IP Input Sheet'!D6<>"",'IP Input Sheet'!D6,IF('IP Input Sheet'!E6<>"",'IP Input Sheet'!E6,'IP Input Sheet'!F6)),"[Enter IP]") | E19: DNS Server | F19: ='IP Input Sheet'!D60 | G19: 53 | H19: TCP/UDP | I19: DNS resolution | J19: Allow | K19: Gateway FW | L19: Outbound
A20: VO-03 | B20: VCF Ops → LDAP | C20: VCF Operations (VCFO) | D20: =IFERROR(IF('IP Input Sheet'!D6<>"",'IP Input Sheet'!D6,IF('IP Input Sheet'!E6<>"",'IP Input Sheet'!E6,'IP Input Sheet'!F6)),"[Enter IP]") | E20: AD/LDAP Server | G20: 389 | H20: TCP | I20: LDAP directory | J20: Allow | K20: Gateway FW | L20: Outbound
A21: VO-04 | B21: VCF Ops → LDAPS | C21: VCF Operations (VCFO) | D21: =IFERROR(IF('IP Input Sheet'!D6<>"",'IP Input Sheet'!D6,IF('IP Input Sheet'!E6<>"",'IP Input Sheet'!E6,'IP Input Sheet'!F6)),"[Enter IP]") | E21: AD/LDAP Server | G21: 636 | H21: TCP | I21: LDAPS secure directory | J21: Allow | K21: Gateway FW | L21: Outbound
A22: VO-05 | B22: VCF Ops → Global Catalog | C22: VCF Operations (VCFO) | D22: =IFERROR(IF('IP Input Sheet'!D6<>"",'IP Input Sheet'!D6,IF('IP Input Sheet'!E6<>"",'IP Input Sheet'!E6,'IP Input Sheet'!F6)),"[Enter IP]") | E22: AD/LDAP Server | G22: 3268/3269 | H22: TCP | I22: Global Catalog AD | J22: Allow | K22: Gateway FW | L22: Outbound
A23: VO-06 | B23: VCF Ops → SFTP | C23: VCF Operations (VCFO) | D23: =IFERROR(IF('IP Input Sheet'!D6<>"",'IP Input Sheet'!D6,IF('IP Input Sheet'!E6<>"",'IP Input Sheet'!E6,'IP Input Sheet'!F6)),"[Enter IP]") | E23: SFTP Server | F23: =IF('IP Input Sheet'!$D$64<>"",'IP Input Sheet'!$D$64,IF('IP Input Sheet'!$E$64<>"",'IP Input Sheet'!$E$64,'IP Input Sheet'!$F$64)) | G23: 22 | H23: TCP | I23: SFTP Backup – TCP/22 | J23: Allow | K23: Gateway FW | L23: Outbound | N23: Normalized SFTP backup entry linked to IP Input Sheet (SFTP_SRV).
A24: VO-07 | B24: VCF Ops → vCenter (inventory) | C24: VCF Operations (VCFO) | D24: =IFERROR(IF('IP Input Sheet'!D6<>"",'IP Input Sheet'!D6,IF('IP Input Sheet'!E6<>"",'IP Input Sheet'!E6,'IP Input Sheet'!F6)),"[Enter IP]") | E24: vCenter Server | F24: =IFERROR(IF('IP Input Sheet'!D13<>"",'IP Input Sheet'!D13,IF('IP Input Sheet'!E13<>"",'IP Input Sheet'!E13,'IP Input Sheet'!F13)),"[Enter IP]") | G24: 10443 | H24: TCP | I24: vCenter inventory service | J24: Allow | K24: Gateway FW | L24: Outbound
A25: VO-08 | B25: VCF Ops → vCenter (HTTPS) | C25: VCF Operations (VCFO) | D25: =IFERROR(IF('IP Input Sheet'!D6<>"",'IP Input Sheet'!D6,IF('IP Input Sheet'!E6<>"",'IP Input Sheet'!E6,'IP Input Sheet'!F6)),"[Enter IP]") | E25: vCenter Server | F25: =IFERROR(IF('IP Input Sheet'!D13<>"",'IP Input Sheet'!D13,IF('IP Input Sheet'!E13<>"",'IP Input Sheet'!E13,'IP Input Sheet'!F13)),"[Enter IP]") | G25: 443 | H25: TCP | I25: HTTPS API comms | J25: Allow | K25: Gateway FW | L25: Outbound
A26: VO-09 | B26: VCF Ops → ESXi | C26: VCF Operations (VCFO) | D26: =IFERROR(IF('IP Input Sheet'!D6<>"",'IP Input Sheet'!D6,IF('IP Input Sheet'!E6<>"",'IP Input Sheet'!E6,'IP Input Sheet'!F6)),"[Enter IP]") | E26: ESXi Hosts (WLD) | F26: =IFERROR(IF('IP Input Sheet'!D54<>"",'IP Input Sheet'!D54,IF('IP Input Sheet'!E54<>"",'IP Input Sheet'!E54,'IP Input Sheet'!F54)),"[Enter IP]") | G26: 443 | H26: TCP | I26: Management operations | J26: Allow | K26: Gateway FW | L26: Outbound
A27: VO-10 | B27: VCF Ops → NSX Manager | C27: VCF Operations (VCFO) | D27: =IFERROR(IF('IP Input Sheet'!D6<>"",'IP Input Sheet'!D6,IF('IP Input Sheet'!E6<>"",'IP Input Sheet'!E6,'IP Input Sheet'!F6)),"[Enter IP]") | E27: NSX Manager | F27: =IFERROR(IF('IP Input Sheet'!D14<>"",'IP Input Sheet'!D14,IF('IP Input Sheet'!E14<>"",'IP Input Sheet'!E14,'IP Input Sheet'!F14)),"[Enter IP]") | G27: 443 | H27: TCP | I27: NSX API metrics/inventory | J27: Allow | K27: Gateway FW | L27: Outbound
A28: VA-01 | B28: VCF Auto → vCenter | C28: VCF Automation (VCFA) | D28: =IFERROR(IF('IP Input Sheet'!D7<>"",'IP Input Sheet'!D7,IF('IP Input Sheet'!E7<>"",'IP Input Sheet'!E7,'IP Input Sheet'!F7)),"[Enter IP]") | E28: vCenter Server | F28: =IFERROR(IF('IP Input Sheet'!D13<>"",'IP Input Sheet'!D13,IF('IP Input Sheet'!E13<>"",'IP Input Sheet'!E13,'IP Input Sheet'!F13)),"[Enter IP]") | G28: 443 | H28: TCP | I28: API and Web Access — mgmt+API | J28: Allow | K28: Gateway FW | L28: Bidirectional
A29: VA-02 | B29: VCF Auto → ESXi (902) | C29: VCF Automation (VCFA) | D29: =IFERROR(IF('IP Input Sheet'!D7<>"",'IP Input Sheet'!D7,IF('IP Input Sheet'!E7<>"",'IP Input Sheet'!E7,'IP Input Sheet'!F7)),"[Enter IP]") | E29: ESXi Hosts (WLD) | F29: =IFERROR(IF('IP Input Sheet'!D54<>"",'IP Input Sheet'!D54,IF('IP Input Sheet'!E54<>"",'IP Input Sheet'!E54,'IP Input Sheet'!F54)),"[Enter IP]") | G29: 902 | H29: TCP | I29: VM Console VMRC/MKS | J29: Allow | K29: Gateway FW | L29: Outbound
A30: VA-03 | B30: VCF Auto → ESXi (443) | C30: VCF Automation (VCFA) | D30: =IFERROR(IF('IP Input Sheet'!D7<>"",'IP Input Sheet'!D7,IF('IP Input Sheet'!E7<>"",'IP Input Sheet'!E7,'IP Input Sheet'!F7)),"[Enter IP]") | E30: ESXi Hosts (WLD) | F30: =IFERROR(IF('IP Input Sheet'!D54<>"",'IP Input Sheet'!D54,IF('IP Input Sheet'!E54<>"",'IP Input Sheet'!E54,'IP Input Sheet'!F54)),"[Enter IP]") | G30: 443 | H30: TCP | I30: Web Console | J30: Allow | K30: Gateway FW | L30: Bidirectional
A31: VA-04 | B31: VCF Auto → ESXi (SSH) | C31: VCF Automation (VCFA) | D31: =IFERROR(IF('IP Input Sheet'!D7<>"",'IP Input Sheet'!D7,IF('IP Input Sheet'!E7<>"",'IP Input Sheet'!E7,'IP Input Sheet'!F7)),"[Enter IP]") | E31: ESXi Hosts (WLD) | F31: =IFERROR(IF('IP Input Sheet'!D54<>"",'IP Input Sheet'!D54,IF('IP Input Sheet'!E54<>"",'IP Input Sheet'!E54,'IP Input Sheet'!F54)),"[Enter IP]") | G31: 22 | H31: TCP | I31: SSH | J31: Allow | K31: Gateway FW | L31: Bidirectional | M31: Admin restrict to jump host
A32: VA-05 | B32: VCF Auto → NSX Mgr | C32: VCF Automation (VCFA) | D32: =IFERROR(IF('IP Input Sheet'!D7<>"",'IP Input Sheet'!D7,IF('IP Input Sheet'!E7<>"",'IP Input Sheet'!E7,'IP Input Sheet'!F7)),"[Enter IP]") | E32: NSX Manager Cluster | F32: =IFERROR(IF('IP Input Sheet'!D14<>"",'IP Input Sheet'!D14,IF('IP Input Sheet'!E14<>"",'IP Input Sheet'!E14,'IP Input Sheet'!F14)),"[Enter IP]") | G32: 443 | H32: TCP | I32: NSX Manager API HTTPS — policy provisioning | J32: Allow | K32: Gateway FW | L32: Bidirectional
A33: VA-06 | B33: VCF Auto → Supervisor VIP (443) | C33: VCF Automation (VCFA) | D33: =IFERROR(IF('IP Input Sheet'!D7<>"",'IP Input Sheet'!D7,IF('IP Input Sheet'!E7<>"",'IP Input Sheet'!E7,'IP Input Sheet'!F7)),"[Enter IP]") | E33: Supervisor Control Plane VIP | F33: =IFERROR(IF('IP Input Sheet'!D13<>"",'IP Input Sheet'!D13,IF('IP Input Sheet'!E13<>"",'IP Input Sheet'!E13,'IP Input Sheet'!F13)),"[Enter IP]") | G33: 443 | H33: TCP | I33: vSphere Supervisor API via LB | J33: Allow | K33: Gateway FW | L33: Outbound
A34: VA-07 | B34: VCF Auto → Supervisor VIP (6443) | C34: VCF Automation (VCFA) | D34: =IFERROR(IF('IP Input Sheet'!D7<>"",'IP Input Sheet'!D7,IF('IP Input Sheet'!E7<>"",'IP Input Sheet'!E7,'IP Input Sheet'!F7)),"[Enter IP]") | E34: Supervisor Control Plane VIP | F34: =IFERROR(IF('IP Input Sheet'!D13<>"",'IP Input Sheet'!D13,IF('IP Input Sheet'!E13<>"",'IP Input Sheet'!E13,'IP Input Sheet'!F13)),"[Enter IP]") | G34: 6443 | H34: TCP | I34: Kubernetes API server | J34: Allow | K34: Gateway FW | L34: Outbound
A35: VN-01 | B35: VON → vCenter (IPFIX) | C35: VCF Ops for Networks (VON) | D35: =IFERROR(IF('IP Input Sheet'!D9<>"",'IP Input Sheet'!D9,IF('IP Input Sheet'!E9<>"",'IP Input Sheet'!E9,'IP Input Sheet'!F9)),"[Enter IP]") | E35: vCenter Server | F35: =IFERROR(IF('IP Input Sheet'!D13<>"",'IP Input Sheet'!D13,IF('IP Input Sheet'!E13<>"",'IP Input Sheet'!E13,'IP Input Sheet'!F13)),"[Enter IP]") | G35: 2055 | H35: TCP | I35: IPFIX (deprecated → use 4739) | J35: Allow | K35: Gateway FW | L35: Outbound | M35: Port 2055 deprecated
A36: VN-02 | B36: VON → ESXi (IPFIX) | C36: VCF Ops for Networks (VON) | D36: =IFERROR(IF('IP Input Sheet'!D9<>"",'IP Input Sheet'!D9,IF('IP Input Sheet'!E9<>"",'IP Input Sheet'!E9,'IP Input Sheet'!F9)),"[Enter IP]") | E36: ESXi Hosts (WLD) | F36: =IFERROR(IF('IP Input Sheet'!D54<>"",'IP Input Sheet'!D54,IF('IP Input Sheet'!E54<>"",'IP Input Sheet'!E54,'IP Input Sheet'!F54)),"[Enter IP]") | G36: 4739 | H36: TCP/UDP | I36: IPFIX + NETFLOW export | J36: Allow | K36: Gateway FW | L36: Outbound
A37: VN-03 | B37: VON → NSX Manager | C37: VCF Ops for Networks (VON) | D37: =IFERROR(IF('IP Input Sheet'!D9<>"",'IP Input Sheet'!D9,IF('IP Input Sheet'!E9<>"",'IP Input Sheet'!E9,'IP Input Sheet'!F9)),"[Enter IP]") | E37: NSX Manager | F37: =IFERROR(IF('IP Input Sheet'!D14<>"",'IP Input Sheet'!D14,IF('IP Input Sheet'!E14<>"",'IP Input Sheet'!E14,'IP Input Sheet'!F14)),"[Enter IP]") | G37: 443 | H37: TCP | I37: HTTPS NSX API — inventory+config+events | J37: Allow | K37: Gateway FW | L37: Outbound
A38: VN-04 | B38: VON → DNS | C38: VCF Ops for Networks (VON) | D38: =IFERROR(IF('IP Input Sheet'!D9<>"",'IP Input Sheet'!D9,IF('IP Input Sheet'!E9<>"",'IP Input Sheet'!E9,'IP Input Sheet'!F9)),"[Enter IP]") | E38: DNS Server | F38: ='IP Input Sheet'!D60 | G38: 53 | H38: TCP | I38: DNS name resolution | J38: Allow | K38: Gateway FW | L38: Outbound
A39: VN-05 | B39: VON → NTP | C39: VCF Ops for Networks (VON) | D39: =IFERROR(IF('IP Input Sheet'!D9<>"",'IP Input Sheet'!D9,IF('IP Input Sheet'!E9<>"",'IP Input Sheet'!E9,'IP Input Sheet'!F9)),"[Enter IP]") | E39: NTP Server | F39: ='IP Input Sheet'!D61 | G39: 123 | H39: UDP | I39: Time server | J39: Allow | K39: Gateway FW | L39: Outbound
A40: VN-06 | B40: VON → Switches (SNMP) | C40: VCF Ops for Networks (VON) | D40: =IFERROR(IF('IP Input Sheet'!D9<>"",'IP Input Sheet'!D9,IF('IP Input Sheet'!E9<>"",'IP Input Sheet'!E9,'IP Input Sheet'!F9)),"[Enter IP]") | E40: Multi-Vendor Switches/Routers | F40: [Physical Device IPs] | G40: 161 | H40: TCP | I40: SNMP Polling | J40: Allow | K40: Gateway FW | L40: Outbound | M40: Confirm physical device IPs with network team
...

Sheet Mgmt+WLD → Fleet
A1: AES-220 | Firewall Rules | Management Domain & WLD ESXi → Fleet
A2: Source IP and Destination IP auto-populate from 'IP Input Sheet'. Fill in IPs there first.
A3: # | B3: Rule Name | C3: Source Component | D3: Source IP / Subnet | E3: Destination Component | F3: Destination IP / Subnet | G3: Port | H3: Protocol | I3: Service / Application | J3: Action | K3: Firewall Type | L3: Flow Direction | M3: Notes
A4: MF-01 | B4: vCenter → Fleet Mgr (HTTPS) | C4: vCenter Server | D4: =IFERROR(IF('IP Input Sheet'!D13<>"",'IP Input Sheet'!D13,IF('IP Input Sheet'!E13<>"",'IP Input Sheet'!E13,'IP Input Sheet'!F13)),"[Enter IP]") | E4: VCF Ops Fleet Manager | F4: =IFERROR(IF('IP Input Sheet'!D5<>"",'IP Input Sheet'!D5,IF('IP Input Sheet'!E5<>"",'IP Input Sheet'!E5,'IP Input Sheet'!F5)),"[Enter IP]") | G4: 443 | H4: TCP | I4: Core APIs/HTTPS lifecycle+orchestration | J4: Allow | K4: Gateway FW | L4: Outbound | M4: Ticket req #4 Mgmt→Fleet
A5: MF-02 | B5: vCenter → VCFO (API) | C5: vCenter Server | D5: =IFERROR(IF('IP Input Sheet'!D13<>"",'IP Input Sheet'!D13,IF('IP Input Sheet'!E13<>"",'IP Input Sheet'!E13,'IP Input Sheet'!F13)),"[Enter IP]") | E5: VCF Operations (VCFO) | F5: =IFERROR(IF('IP Input Sheet'!D6<>"",'IP Input Sheet'!D6,IF('IP Input Sheet'!E6<>"",'IP Input Sheet'!E6,'IP Input Sheet'!F6)),"[Enter IP]") | G5: 443 | H5: TCP | I5: API comms bidirectional | J5: Allow | K5: Gateway FW | L5: Bidirectional
A6: MF-03 | B6: vCenter → VCFO (node mgr) | C6: vCenter Server | D6: =IFERROR(IF('IP Input Sheet'!D13<>"",'IP Input Sheet'!D13,IF('IP Input Sheet'!E13<>"",'IP Input Sheet'!E13,'IP Input Sheet'!F13)),"[Enter IP]") | E6: VCF Operations (VCFO) | F6: =IFERROR(IF('IP Input Sheet'!D6<>"",'IP Input Sheet'!D6,IF('IP Input Sheet'!E6<>"",'IP Input Sheet'!E6,'IP Input Sheet'!F6)),"[Enter IP]") | G6: 8443 | H6: TCP | I6: Node Manager | J6: Allow | K6: Gateway FW | L6: Outbound
A7: MF-04 | B7: vCenter → VCFA (API) | C7: vCenter Server | D7: =IFERROR(IF('IP Input Sheet'!D13<>"",'IP Input Sheet'!D13,IF('IP Input Sheet'!E13<>"",'IP Input Sheet'!E13,'IP Input Sheet'!F13)),"[Enter IP]") | E7: VCF Automation (VCFA) | F7: =IFERROR(IF('IP Input Sheet'!D7<>"",'IP Input Sheet'!D7,IF('IP Input Sheet'!E7<>"",'IP Input Sheet'!E7,'IP Input Sheet'!F7)),"[Enter IP]") | G7: 443 | H7: TCP | I7: API bidirectional | J7: Allow | K7: Gateway FW | L7: Bidirectional
A8: MF-05 | B8: vCenter → VOL (syslog) | C8: vCenter Server | D8: =IFERROR(IF('IP Input Sheet'!D13<>"",'IP Input Sheet'!D13,IF('IP Input Sheet'!E13<>"",'IP Input Sheet'!E13,'IP Input Sheet'!F13)),"[Enter IP]") | E8: VCF Operations for Logs | F8: =IFERROR(IF('IP Input Sheet'!D8<>"",'IP Input Sheet'!D8,IF('IP Input Sheet'!E8<>"",'IP Input Sheet'!E8,'IP Input Sheet'!F8)),"[Enter IP]") | G8: 514 | H8: TCP/UDP | I8: Syslog remote logging | J8: Allow | K8: Gateway FW | L8: Outbound
A9: MF-06 | B9: vCenter → VOL (syslog TLS) | C9: vCenter Server | D9: =IFERROR(IF('IP Input Sheet'!D13<>"",'IP Input Sheet'!D13,IF('IP Input Sheet'!E13<>"",'IP Input Sheet'!E13,'IP Input Sheet'!F13)),"[Enter IP]") | E9: VCF Operations for Logs | F9: =IFERROR(IF('IP Input Sheet'!D8<>"",'IP Input Sheet'!D8,IF('IP Input Sheet'!E8<>"",'IP Input Sheet'!E8,'IP Input Sheet'!F8)),"[Enter IP]") | G9: 1514 | H9: TCP | I9: Syslog over TLS | J9: Allow | K9: Gateway FW | L9: Outbound
A10: MF-07 | B10: vCenter → VON (IPFIX) | C10: vCenter Server | D10: =IFERROR(IF('IP Input Sheet'!D13<>"",'IP Input Sheet'!D13,IF('IP Input Sheet'!E13<>"",'IP Input Sheet'!E13,'IP Input Sheet'!F13)),"[Enter IP]") | E10: VCF Ops for Networks | F10: =IFERROR(IF('IP Input Sheet'!D9<>"",'IP Input Sheet'!D9,IF('IP Input Sheet'!E9<>"",'IP Input Sheet'!E9,'IP Input Sheet'!F9)),"[Enter IP]") | G10: 2055 | H10: UDP | I10: IPFIX flow data vDS→NSX | J10: Allow | K10: Gateway FW | L10: Outbound | M10: vDS distributed switches send IPFIX
A11: MF-08 | B11: NSX Manager → VCFO (API) | C11: NSX Manager | D11: =IFERROR(IF('IP Input Sheet'!D14<>"",'IP Input Sheet'!D14,IF('IP Input Sheet'!E14<>"",'IP Input Sheet'!E14,'IP Input Sheet'!F14)),"[Enter IP]") | E11: VCF Operations (VCFO) | F11: =IFERROR(IF('IP Input Sheet'!D6<>"",'IP Input Sheet'!D6,IF('IP Input Sheet'!E6<>"",'IP Input Sheet'!E6,'IP Input Sheet'!F6)),"[Enter IP]") | G11: 443 | H11: TCP | I11: API/inventory collection | J11: Allow | K11: Gateway FW | L11: Outbound
A12: MF-09 | B12: NSX Mgr → VOL (syslog) | C12: NSX Manager | D12: =IFERROR(IF('IP Input Sheet'!D14<>"",'IP Input Sheet'!D14,IF('IP Input Sheet'!E14<>"",'IP Input Sheet'!E14,'IP Input Sheet'!F14)),"[Enter IP]") | E12: VCF Operations for Logs | F12: =IFERROR(IF('IP Input Sheet'!D8<>"",'IP Input Sheet'!D8,IF('IP Input Sheet'!E8<>"",'IP Input Sheet'!E8,'IP Input Sheet'!F8)),"[Enter IP]") | G12: 514 | H12: TCP/UDP | I12: NSX node syslog | J12: Allow | K12: Gateway FW | L12: Outbound
A13: MF-10 | B13: NSX Mgr → VOL (syslog TLS) | C13: NSX Manager | D13: =IFERROR(IF('IP Input Sheet'!D14<>"",'IP Input Sheet'!D14,IF('IP Input Sheet'!E14<>"",'IP Input Sheet'!E14,'IP Input Sheet'!F14)),"[Enter IP]") | E13: VCF Operations for Logs | F13: =IFERROR(IF('IP Input Sheet'!D8<>"",'IP Input Sheet'!D8,IF('IP Input Sheet'!E8<>"",'IP Input Sheet'!E8,'IP Input Sheet'!F8)),"[Enter IP]") | G13: 6514 | H13: TCP | I13: Syslog over TLS | J13: Allow | K13: Gateway FW | L13: Outbound
A14: MF-11 | B14: SDDC Mgr → Fleet Mgr (HTTPS) | C14: SDDC Manager | D14: =IFERROR(IF('IP Input Sheet'!D16<>"",'IP Input Sheet'!D16,IF('IP Input Sheet'!E16<>"",'IP Input Sheet'!E16,'IP Input Sheet'!F16)),"[Enter IP]") | E14: VCF Ops Fleet Manager | F14: =IFERROR(IF('IP Input Sheet'!D5<>"",'IP Input Sheet'!D5,IF('IP Input Sheet'!E5<>"",'IP Input Sheet'!E5,'IP Input Sheet'!F5)),"[Enter IP]") | G14: 443 | H14: TCP | I14: HTTPS+API — fleet orchestration | J14: Allow | K14: Gateway FW | L14: Outbound
A15: MF-12 | B15: SDDC Mgr → Fleet Mgr (SSH) | C15: SDDC Manager | D15: =IFERROR(IF('IP Input Sheet'!D16<>"",'IP Input Sheet'!D16,IF('IP Input Sheet'!E16<>"",'IP Input Sheet'!E16,'IP Input Sheet'!F16)),"[Enter IP]") | E15: VCF Ops Fleet Manager | F15: =IFERROR(IF('IP Input Sheet'!D5<>"",'IP Input Sheet'!D5,IF('IP Input Sheet'!E5<>"",'IP Input Sheet'!E5,'IP Input Sheet'!F5)),"[Enter IP]") | G15: 22 | H15: TCP | I15: SSH — deployment+troubleshooting | J15: Allow | K15: Gateway FW | L15: Outbound | M15: Admin restrict to jump host
A16: MF-13 | B16: SDDC Mgr → VCFA (HTTPS) | C16: SDDC Manager | D16: =IFERROR(IF('IP Input Sheet'!D16<>"",'IP Input Sheet'!D16,IF('IP Input Sheet'!E16<>"",'IP Input Sheet'!E16,'IP Input Sheet'!F16)),"[Enter IP]") | E16: VCF Automation (VCFA) | F16: =IFERROR(IF('IP Input Sheet'!D7<>"",'IP Input Sheet'!D7,IF('IP Input Sheet'!E7<>"",'IP Input Sheet'!E7,'IP Input Sheet'!F7)),"[Enter IP]") | G16: 443 | H16: TCP | I16: API access management | J16: Allow | K16: Gateway FW | L16: Outbound
A17: MF-14 | B17: SDDC Mgr → VCFA (SSH) | C17: SDDC Manager | D17: =IFERROR(IF('IP Input Sheet'!D16<>"",'IP Input Sheet'!D16,IF('IP Input Sheet'!E16<>"",'IP Input Sheet'!E16,'IP Input Sheet'!F16)),"[Enter IP]") | E17: VCF Automation (VCFA) | F17: =IFERROR(IF('IP Input Sheet'!D7<>"",'IP Input Sheet'!D7,IF('IP Input Sheet'!E7<>"",'IP Input Sheet'!E7,'IP Input Sheet'!F7)),"[Enter IP]") | G17: 22 | H17: TCP | I17: SSH cluster nodes | J17: Allow | K17: Gateway FW | L17: Outbound | M17: Admin restrict to jump host
A18: MF-15 | B18: SDDC Mgr → VCFO (HTTPS) | C18: SDDC Manager | D18: =IFERROR(IF('IP Input Sheet'!D16<>"",'IP Input Sheet'!D16,IF('IP Input Sheet'!E16<>"",'IP Input Sheet'!E16,'IP Input Sheet'!F16)),"[Enter IP]") | E18: VCF Operations (VCFO) | F18: =IFERROR(IF('IP Input Sheet'!D6<>"",'IP Input Sheet'!D6,IF('IP Input Sheet'!E6<>"",'IP Input Sheet'!E6,'IP Input Sheet'!F6)),"[Enter IP]") | G18: 443 | H18: TCP | I18: API access cluster+nodes | J18: Allow | K18: Gateway FW | L18: Outbound
A19: MF-16 | B19: SDDC Mgr → VCFO (SSH) | C19: SDDC Manager | D19: =IFERROR(IF('IP Input Sheet'!D16<>"",'IP Input Sheet'!D16,IF('IP Input Sheet'!E16<>"",'IP Input Sheet'!E16,'IP Input Sheet'!F16)),"[Enter IP]") | E19: VCF Operations (VCFO) | F19: =IFERROR(IF('IP Input Sheet'!D6<>"",'IP Input Sheet'!D6,IF('IP Input Sheet'!E6<>"",'IP Input Sheet'!E6,'IP Input Sheet'!F6)),"[Enter IP]") | G19: 22 | H19: TCP | I19: SSH cluster+collector nodes | J19: Allow | K19: Gateway FW | L19: Outbound | M19: Admin restrict to jump host
A20: MF-16b | B20: SDDC Mgr → vCenter (SSH) | C20: SDDC Manager | D20: =IFERROR(IF('IP Input Sheet'!D16<>"",'IP Input Sheet'!D16,IF('IP Input Sheet'!E16<>"",'IP Input Sheet'!E16,'IP Input Sheet'!F16)),"[Enter IP]") | E20: vCenter Server | F20: =IFERROR(IF('IP Input Sheet'!D13<>"",'IP Input Sheet'!D13,IF('IP Input Sheet'!E13<>"",'IP Input Sheet'!E13,'IP Input Sheet'!F13)),"[Enter IP]") | G20: 22 | H20: TCP | I20: SSH — SDDC Manager to vCenter | J20: Allow | K20: Gateway FW | L20: Outbound | M20: Added per Arun — SDDC Mgr → vCenter port 22 | N20: ⭐ NEW
A21: MF-16c | B21: SDDC Mgr → ESXi Hosts (SSH) | C21: SDDC Manager | D21: =IFERROR(IF('IP Input Sheet'!D16<>"",'IP Input Sheet'!D16,IF('IP Input Sheet'!E16<>"",'IP Input Sheet'!E16,'IP Input Sheet'!F16)),"[Enter IP]") | E21: ESXi Hosts (WLD) | F21: =IFERROR(IF('IP Input Sheet'!D54<>"",'IP Input Sheet'!D54,IF('IP Input Sheet'!E54<>"",'IP Input Sheet'!E54,'IP Input Sheet'!F54)),"[Enter IP]") | G21: 22 | H21: TCP | I21: SSH — SDDC Manager to ESXi hosts | J21: Allow | K21: Gateway FW | L21: Outbound | M21: Added per Arun — SDDC Mgr → ESXi port 22 | N21: ⭐ NEW
A22: MF-17 | B22: SDDC Mgr → VOL (syslog) | C22: SDDC Manager | D22: =IFERROR(IF('IP Input Sheet'!D16<>"",'IP Input Sheet'!D16,IF('IP Input Sheet'!E16<>"",'IP Input Sheet'!E16,'IP Input Sheet'!F16)),"[Enter IP]") | E22: VCF Operations for Logs | F22: =IFERROR(IF('IP Input Sheet'!D8<>"",'IP Input Sheet'!D8,IF('IP Input Sheet'!E8<>"",'IP Input Sheet'!E8,'IP Input Sheet'!F8)),"[Enter IP]") | G22: 514 | H22: TCP | I22: Syslog based logging | J22: Allow | K22: Gateway FW | L22: Outbound
A23: MF-18 | B23: SDDC Mgr → VOL (9000) | C23: SDDC Manager | D23: =IFERROR(IF('IP Input Sheet'!D16<>"",'IP Input Sheet'!D16,IF('IP Input Sheet'!E16<>"",'IP Input Sheet'!E16,'IP Input Sheet'!F16)),"[Enter IP]") | E23: VCF Operations for Logs | F23: =IFERROR(IF('IP Input Sheet'!D8<>"",'IP Input Sheet'!D8,IF('IP Input Sheet'!E8<>"",'IP Input Sheet'!E8,'IP Input Sheet'!F8)),"[Enter IP]") | G23: 9000 | H23: TCP | I23: Log ingestion API CFAPI unencrypted | J23: Allow | K23: Gateway FW | L23: Outbound
A24: MF-19 | B24: SDDC Mgr → VOL (HTTPS) | C24: SDDC Manager | D24: =IFERROR(IF('IP Input Sheet'!D16<>"",'IP Input Sheet'!D16,IF('IP Input Sheet'!E16<>"",'IP Input Sheet'!E16,'IP Input Sheet'!F16)),"[Enter IP]") | E24: VCF Operations for Logs | F24: =IFERROR(IF('IP Input Sheet'!D8<>"",'IP Input Sheet'!D8,IF('IP Input Sheet'!E8<>"",'IP Input Sheet'!E8,'IP Input Sheet'!F8)),"[Enter IP]") | G24: 443 | H24: TCP | I24: Logs cluster VIP+nodes | J24: Allow | K24: Gateway FW | L24: Outbound
A25: MF-20 | B25: SDDC Mgr → VOL (9543) | C25: SDDC Manager | D25: =IFERROR(IF('IP Input Sheet'!D16<>"",'IP Input Sheet'!D16,IF('IP Input Sheet'!E16<>"",'IP Input Sheet'!E16,'IP Input Sheet'!F16)),"[Enter IP]") | E25: VCF Operations for Logs | F25: =IFERROR(IF('IP Input Sheet'!D8<>"",'IP Input Sheet'!D8,IF('IP Input Sheet'!E8<>"",'IP Input Sheet'!E8,'IP Input Sheet'!F8)),"[Enter IP]") | G25: 9543 | H25: TCP | I25: API access management ops | J25: Allow | K25: Gateway FW | L25: Outbound
A26: MF-21 | B26: SDDC Mgr → VIDB (HTTPS) | C26: SDDC Manager | D26: =IFERROR(IF('IP Input Sheet'!D16<>"",'IP Input Sheet'!D16,IF('IP Input Sheet'!E16<>"",'IP Input Sheet'!E16,'IP Input Sheet'!F16)),"[Enter IP]") | E26: Identity Broker (VIDB) | F26: =IFERROR(IF('IP Input Sheet'!D10<>"",'IP Input Sheet'!D10,IF('IP Input Sheet'!E10<>"",'IP Input Sheet'!E10,'IP Input Sheet'!F10)),"[Enter IP]") | G26: 443 | H26: TCP | I26: VCF SSO API — SDDC Mgr auth | J26: Allow | K26: Gateway FW | L26: Outbound | M26: Critical SSO dependency
A27: MF-22 | B27: SDDC Mgr → VIDB (SSH) | C27: SDDC Manager | D27: =IFERROR(IF('IP Input Sheet'!D16<>"",'IP Input Sheet'!D16,IF('IP Input Sheet'!E16<>"",'IP Input Sheet'!E16,'IP Input Sheet'!F16)),"[Enter IP]") | E27: Identity Broker (VIDB) | F27: =IFERROR(IF('IP Input Sheet'!D10<>"",'IP Input Sheet'!D10,IF('IP Input Sheet'!E10<>"",'IP Input Sheet'!E10,'IP Input Sheet'!F10)),"[Enter IP]") | G27: 22 | H27: TCP | I27: SSH SSO bringup ops | J27: Allow | K27: Gateway FW | L27: Outbound | M27: Admin — restrict to jump host
A28: MF-23 | B28: ESXi → VOL (syslog) | C28: ESXi Hosts (WLD) | D28: =IFERROR(IF('IP Input Sheet'!D54<>"",'IP Input Sheet'!D54,IF('IP Input Sheet'!E54<>"",'IP Input Sheet'!E54,'IP Input Sheet'!F54)),"[Enter IP]") | E28: VCF Operations for Logs | F28: =IFERROR(IF('IP Input Sheet'!D8<>"",'IP Input Sheet'!D8,IF('IP Input Sheet'!E8<>"",'IP Input Sheet'!E8,'IP Input Sheet'!F8)),"[Enter IP]") | G28: 514 | H28: TCP/UDP | I28: vSphere host syslog to VOL | J28: Allow | K28: Gateway FW | L28: Outbound | M28: Ticket req #4 — ESXi→Fleet
A29: MF-24 | B29: ESXi → VOL (syslog TLS) | C29: ESXi Hosts (WLD) | D29: =IFERROR(IF('IP Input Sheet'!D54<>"",'IP Input Sheet'!D54,IF('IP Input Sheet'!E54<>"",'IP Input Sheet'!E54,'IP Input Sheet'!F54)),"[Enter IP]") | E29: VCF Operations for Logs | F29: =IFERROR(IF('IP Input Sheet'!D8<>"",'IP Input Sheet'!D8,IF('IP Input Sheet'!E8<>"",'IP Input Sheet'!E8,'IP Input Sheet'!F8)),"[Enter IP]") | G29: 1514 | H29: TCP | I29: Secure syslog over TLS | J29: Allow | K29: Gateway FW | L29: Outbound
A30: MF-25 | B30: ESXi → VON (IPFIX) | C30: ESXi Hosts (WLD) | D30: =IFERROR(IF('IP Input Sheet'!D54<>"",'IP Input Sheet'!D54,IF('IP Input Sheet'!E54<>"",'IP Input Sheet'!E54,'IP Input Sheet'!F54)),"[Enter IP]") | E30: VCF Ops for Networks | F30: =IFERROR(IF('IP Input Sheet'!D9<>"",'IP Input Sheet'!D9,IF('IP Input Sheet'!E9<>"",'IP Input Sheet'!E9,'IP Input Sheet'!F9)),"[Enter IP]") | G30: 4739 | H30: TCP/UDP | I30: IPFIX flow export from ESXi | J30: Allow | K30: Gateway FW | L30: Outbound
A31: MF-26 | B31: ESXi (Mgmt) → VOL (syslog) | C31: ESXi Hosts (Mgmt Domain) | D31: =IFERROR(IF('IP Input Sheet'!D18<>"",'IP Input Sheet'!D18,IF('IP Input Sheet'!E18<>"",'IP Input Sheet'!E18,'IP Input Sheet'!F18)),"[Enter IP]") | E31: VCF Operations for Logs | F31: =IFERROR(IF('IP Input Sheet'!D8<>"",'IP Input Sheet'!D8,IF('IP Input Sheet'!E8<>"",'IP Input Sheet'!E8,'IP Input Sheet'!F8)),"[Enter IP]") | G31: 514 | H31: TCP/UDP | I31: Mgmt domain ESXi syslog | J31: Allow | K31: Gateway FW | L31: Outbound
A32: MF-27 | B32: ESXi (Mgmt) → VOL (TLS) | C32: ESXi Hosts (Mgmt Domain) | D32: =IFERROR(IF('IP Input Sheet'!D18<>"",'IP Input Sheet'!D18,IF('IP Input Sheet'!E18<>"",'IP Input Sheet'!E18,'IP Input Sheet'!F18)),"[Enter IP]") | E32: VCF Operations for Logs | F32: =IFERROR(IF('IP Input Sheet'!D8<>"",'IP Input Sheet'!D8,IF('IP Input Sheet'!E8<>"",'IP Input Sheet'!E8,'IP Input Sheet'!F8)),"[Enter IP]") | G32: 1514 | H32: TCP | I32: Secure syslog TLS | J32: Allow | K32: Gateway FW | L32: Outbound
A33: MF-28 | B33: ICMP All → Fleet (reachability) | C33: All Mgmt Domain Components | D33: =IFERROR(IF('IP Input Sheet'!D18<>"",'IP Input Sheet'!D18,IF('IP Input Sheet'!E18<>"",'IP Input Sheet'!E18,'IP Input Sheet'!F18)),"[Enter IP]") | E33: All Fleet Components | F33: [All Fleet IPs] | G33: ICMP | H33: ICMP | I33: IP reachability — ping/traceroute | J33: Allow | K33: Gateway FW | L33: Bidirectional | M33: ALL Fleet-level & VCF instance-level — mandatory
A34: MF-29 | B34: VON Collector → VON (HTTPS) | C34: VCF OPS Network Collector (M7) | D34: =IFERROR(IF('IP Input Sheet'!D19<>"",'IP Input Sheet'!D19,IF('IP Input Sheet'!E19<>"",'IP Input Sheet'!E19,'IP Input Sheet'!F19)),"[Enter IP]") | E34: VCF Ops for Networks (VON) | F34: =IFERROR(IF('IP Input Sheet'!D9<>"",'IP Input Sheet'!D9,IF('IP Input Sheet'!E9<>"",'IP Input Sheet'!E9,'IP Input Sheet'!F9)),"[Enter IP]") | G34: 443 | H34: TCP | I34: Collector → VON bidirectional API | J34: Allow | K34: Gateway FW | L34: Outbound | M34: M7 — added per Raju
A35: MF-30 | B35: VON Collector → NSX Manager | C35: VCF OPS Network Collector (M7) | D35: =IFERROR(IF('IP Input Sheet'!D19<>"",'IP Input Sheet'!D19,IF('IP Input Sheet'!E19<>"",'IP Input Sheet'!E19,'IP Input Sheet'!F19)),"[Enter IP]") | E35: NSX Manager | F35: =IFERROR(IF('IP Input Sheet'!D14<>"",'IP Input Sheet'!D14,IF('IP Input Sheet'!E14<>"",'IP Input Sheet'!E14,'IP Input Sheet'!F14)),"[Enter IP]") | G35: 443 | H35: TCP | I35: Collector pulls NSX flow/topology data | J35: Allow | K35: Gateway FW | L35: Outbound | M35: M7 — per Raju
A36: MF-31 | B36: VON Collector → vCenter | C36: VCF OPS Network Collector (M7) | D36: =IFERROR(IF('IP Input Sheet'!D19<>"",'IP Input Sheet'!D19,IF('IP Input Sheet'!E19<>"",'IP Input Sheet'!E19,'IP Input Sheet'!F19)),"[Enter IP]") | E36: vCenter Server | F36: =IFERROR(IF('IP Input Sheet'!D13<>"",'IP Input Sheet'!D13,IF('IP Input Sheet'!E13<>"",'IP Input Sheet'!E13,'IP Input Sheet'!F13)),"[Enter IP]") | G36: 443 | H36: TCP | I36: Collector pulls vCenter inventory | J36: Allow | K36: Gateway FW | L36: Outbound | M36: M7 — per Raju
A37: MF-32 | B37: SDDC Mgr → VON Collector | C37: SDDC Manager | D37: =IFERROR(IF('IP Input Sheet'!D16<>"",'IP Input Sheet'!D16,IF('IP Input Sheet'!E16<>"",'IP Input Sheet'!E16,'IP Input Sheet'!F16)),"[Enter IP]") | E37: VCF OPS Network Collector (M7) | F37: =IFERROR(IF('IP Input Sheet'!D19<>"",'IP Input Sheet'!D19,IF('IP Input Sheet'!E19<>"",'IP Input Sheet'!E19,'IP Input Sheet'!F19)),"[Enter IP]") | G37: 443 | H37: TCP | I37: SDDC lifecycle management of collector | J37: Allow | K37: Gateway FW | L37: Outbound | M37: M7 — per Raju
A38: NSX FEDERATION INTER-SITE RULES (LM ↔ GM) — Added per NSX team requirement
A39: FED-02 | B39: NSX LM → NSX GM — API Sync (reverse) | C39: NSX Local Manager (M2) | D39: =IFERROR(IF('IP Input Sheet'!D14<>"",'IP Input Sheet'!D14,IF('IP Input Sheet'!E14<>"",'IP Input Sheet'!E14,'IP Input Sheet'!F14)),"[Enter IP]") | E39: NSX Global Manager (M3) | F39: =IFERROR(IF('IP Input Sheet'!D15<>"",'IP Input Sheet'!D15,IF('IP Input Sheet'!E15<>"",'IP Input Sheet'!E15,'IP Input Sheet'!F15)),"[Enter IP]") | G39: 443 | H39: TCP | I39: API & Management Plane synchronisation — LM status reporting to GM | J39: Allow | K39: Gateway FW | L39: Outbound | M39: LM→GM TCP 443 bidirectional with FED-01
A40: FED-04 | B40: NSX LM → NSX GM — Async Replication (reverse) | C40: NSX Local Manager (M2) | D40: =IFERROR(IF('IP Input Sheet'!D14<>"",'IP Input Sheet'!D14,IF('IP Input Sheet'!E14<>"",'IP Input Sheet'!E14,'IP Input Sheet'!F14)),"[Enter IP]") | E40: NSX Global Manager (M3) | F40: =IFERROR(IF('IP Input Sheet'!D15<>"",'IP Input Sheet'!D15,IF('IP Input Sheet'!E15<>"",'IP Input Sheet'!E15,'IP Input Sheet'!F15)),"[Enter IP]") | G40: 1236 | H40: TCP | I40: Asynchronous Replication acknowledgement — LM confirms receipt to GM | J40: Allow | K40: Gateway FW | L40: Outbound | M40: TCP 1236 bidirectional with FED-03 — CRITICAL
...

Sheet Fleet → External
A1: AES-220 | Firewall Rules | Fleet → External Services
A2: Source IP and Destination IP auto-populate from '📋 IP Input Sheet'. Fill in IPs there first.
A3: # | B3: Rule Name | C3: Source Component | D3: Source IP / Subnet | E3: Destination Component | F3: Destination IP / Subnet | G3: Port | H3: Protocol | I3: Service / Application | J3: Action | K3: Firewall Type | L3: Flow Direction | M3: Notes
A4: EX-01 | B4: Fleet Mgr → DNS | C4: VCF Operations Fleet Manager | D4: =IFERROR(IF('IP Input Sheet'!D5<>"",'IP Input Sheet'!D5,IF('IP Input Sheet'!E5<>"",'IP Input Sheet'!E5,'IP Input Sheet'!F5)),"[Enter IP]") | E4: DNS Server | F4: ='IP Input Sheet'!D60 | G4: 53 | H4: TCP/UDP | I4: Name resolution | J4: Allow | K4: Gateway FW | L4: Bidirectional | M4: All Fleet+VCF components
A5: EX-02 | B5: Fleet Mgr → NTP | C5: VCF Operations Fleet Manager | D5: =IFERROR(IF('IP Input Sheet'!D5<>"",'IP Input Sheet'!D5,IF('IP Input Sheet'!E5<>"",'IP Input Sheet'!E5,'IP Input Sheet'!F5)),"[Enter IP]") | E5: NTP Server | F5: ='IP Input Sheet'!D61 | G5: 123 | H5: UDP | I5: Time sync | J5: Allow | K5: Gateway FW | L5: Outbound
A6: EX-03 | B6: VCFO → DNS | C6: VCF Operations (VCFO) | D6: =IFERROR(IF('IP Input Sheet'!D6<>"",'IP Input Sheet'!D6,IF('IP Input Sheet'!E6<>"",'IP Input Sheet'!E6,'IP Input Sheet'!F6)),"[Enter IP]") | E6: DNS Server | F6: ='IP Input Sheet'!D60 | G6: 53 | H6: TCP/UDP | I6: DNS | J6: Allow | K6: Gateway FW | L6: Outbound | M6: Primary/Replica/Data nodes
A7: EX-04 | B7: VCFO → NTP | C7: VCF Operations (VCFO) | D7: =IFERROR(IF('IP Input Sheet'!D6<>"",'IP Input Sheet'!D6,IF('IP Input Sheet'!E6<>"",'IP Input Sheet'!E6,'IP Input Sheet'!F6)),"[Enter IP]") | E7: NTP Server | F7: ='IP Input Sheet'!D61 | G7: 123 | H7: UDP | I7: Time sync | J7: Allow | K7: Gateway FW | L7: Outbound
A8: EX-05 | B8: VCFO → LDAP | C8: VCF Operations (VCFO) | D8: =IFERROR(IF('IP Input Sheet'!D6<>"",'IP Input Sheet'!D6,IF('IP Input Sheet'!E6<>"",'IP Input Sheet'!E6,'IP Input Sheet'!F6)),"[Enter IP]") | E8: AD/LDAP Server | G8: 389 | H8: TCP | I8: LDAP directory | J8: Allow | K8: Gateway FW | L8: Outbound
A9: EX-06 | B9: VCFO → LDAPS | C9: VCF Operations (VCFO) | D9: =IFERROR(IF('IP Input Sheet'!D6<>"",'IP Input Sheet'!D6,IF('IP Input Sheet'!E6<>"",'IP Input Sheet'!E6,'IP Input Sheet'!F6)),"[Enter IP]") | E9: AD/LDAP Server | G9: 636 | H9: TCP | I9: Secure LDAP | J9: Allow | K9: Gateway FW | L9: Outbound
A10: EX-07 | B10: VCFO → Global Catalog | C10: VCF Operations (VCFO) | D10: =IFERROR(IF('IP Input Sheet'!D6<>"",'IP Input Sheet'!D6,IF('IP Input Sheet'!E6<>"",'IP Input Sheet'!E6,'IP Input Sheet'!F6)),"[Enter IP]") | E10: AD/LDAP Server | G10: 3268/3269 | H10: TCP | I10: Global Catalog | J10: Allow | K10: Gateway FW | L10: Outbound
A11: EX-08 | B11: VCFO → SFTP | C11: VCF Operations (VCFO) | D11: =IFERROR(IF('IP Input Sheet'!D6<>"",'IP Input Sheet'!D6,IF('IP Input Sheet'!E6<>"",'IP Input Sheet'!E6,'IP Input Sheet'!F6)),"[Enter IP]") | E11: SFTP Server | F11: =IF('IP Input Sheet'!$D$64<>"",'IP Input Sheet'!$D$64,IF('IP Input Sheet'!$E$64<>"",'IP Input Sheet'!$E$64,'IP Input Sheet'!$F$64)) | G11: 22 | H11: TCP | I11: SFTP Backup – TCP/22 | J11: Allow | K11: Gateway FW | L11: Outbound | M11: Normalized SFTP backup entry linked to IP Input Sheet (SFTP_SRV).
A12: EX-09 | B12: VIDB → LDAP | C12: Identity Broker (VIDB) | D12: =IFERROR(IF('IP Input Sheet'!D10<>"",'IP Input Sheet'!D10,IF('IP Input Sheet'!E10<>"",'IP Input Sheet'!E10,'IP Input Sheet'!F10)),"[Enter IP]") | E12: AD/LDAP Server | G12: 389 | H12: TCP/UDP | I12: Directory lookups | J12: Allow | K12: Gateway FW | L12: Outbound | M12: Identity Broker→AD
A13: EX-10 | B13: VIDB → Secure LDAP | C13: Identity Broker (VIDB) | D13: =IFERROR(IF('IP Input Sheet'!D10<>"",'IP Input Sheet'!D10,IF('IP Input Sheet'!E10<>"",'IP Input Sheet'!E10,'IP Input Sheet'!F10)),"[Enter IP]") | E13: AD/LDAP Server | G13: 636 | H13: TCP | I13: Secure LDAP | J13: Allow | K13: Gateway FW | L13: Outbound
A14: EX-11 | B14: VIDB → IdP Federation | C14: Identity Broker (VIDB) | D14: =IFERROR(IF('IP Input Sheet'!D10<>"",'IP Input Sheet'!D10,IF('IP Input Sheet'!E10<>"",'IP Input Sheet'!E10,'IP Input Sheet'!F10)),"[Enter IP]") | E14: IdP Federation Endpoint | F14: [IdP Federation IP] | G14: 443 | H14: TCP | I14: SAML/OIDC/Okta/Ping/Entra ID | J14: Allow | K14: Gateway FW | L14: Outbound | M14: External IdP — confirm IP with AMEX security team
A15: EX-12 | B15: VIDB → DNS | C15: Identity Broker (VIDB) | D15: =IFERROR(IF('IP Input Sheet'!D10<>"",'IP Input Sheet'!D10,IF('IP Input Sheet'!E10<>"",'IP Input Sheet'!E10,'IP Input Sheet'!F10)),"[Enter IP]") | E15: DNS Server | G15: 53 | H15: TCP/UDP | I15: FQDN resolution for vCenter/NSX/SDDC | J15: Allow | K15: Gateway FW | L15: Outbound
A16: EX-13 | B16: VIDB → NTP | C16: Identity Broker (VIDB) | D16: =IFERROR(IF('IP Input Sheet'!D10<>"",'IP Input Sheet'!D10,IF('IP Input Sheet'!E10<>"",'IP Input Sheet'!E10,'IP Input Sheet'!F10)),"[Enter IP]") | E16: NTP Server | G16: 123 | H16: UDP | I16: Time sync | J16: Allow | K16: Gateway FW | L16: Outbound
A17: EX-14 | B17: VIDB → SFTP | C17: Identity Broker (VIDB) | D17: =IFERROR(IF('IP Input Sheet'!D10<>"",'IP Input Sheet'!D10,IF('IP Input Sheet'!E10<>"",'IP Input Sheet'!E10,'IP Input Sheet'!F10)),"[Enter IP]") | E17: SFTP Server | F17: =IF('IP Input Sheet'!$D$64<>"",'IP Input Sheet'!$D$64,IF('IP Input Sheet'!$E$64<>"",'IP Input Sheet'!$E$64,'IP Input Sheet'!$F$64)) | G17: 22 | H17: TCP | I17: SFTP Backup – TCP/22 | J17: Allow | K17: Gateway FW | L17: Outbound | M17: Normalized SFTP backup entry linked to IP Input Sheet (SFTP_SRV).
A18: EX-15 | B18: VIDB → CA Server | C18: Identity Broker (VIDB) | D18: =IFERROR(IF('IP Input Sheet'!D10<>"",'IP Input Sheet'!D10,IF('IP Input Sheet'!E10<>"",'IP Input Sheet'!E10,'IP Input Sheet'!F10)),"[Enter IP]") | E18: CA Certificate Server | G18: 443 | H18: TCP | I18: SSL certificate CA | J18: Allow | K18: Gateway FW | L18: Outbound
A19: EX-16 | B19: ICMP — Fleet→External | C19: All Fleet Components | D19: [Fleet IPs] | E19: External Services | F19: [External IP] | G19: ICMP | H19: ICMP | I19: Reachability ping/traceroute | J19: Allow | K19: Gateway FW | L19: Bidirectional | M19: ALL Fleet-level components
A20: EX-17 | B20: NSX GM → SFTP Backup | C20: NSX Global Manager | D20: =IF('IP Input Sheet'!$D$15<>"",'IP Input Sheet'!$D$15,IF('IP Input Sheet'!$E$15<>"",'IP Input Sheet'!$E$15,'IP Input Sheet'!$F$15)) | E20: SFTP Server | F20: =IF('IP Input Sheet'!$D$64<>"",'IP Input Sheet'!$D$64,IF('IP Input Sheet'!$E$64<>"",'IP Input Sheet'!$E$64,'IP Input Sheet'!$F$64)) | G20: 22 | H20: TCP | I20: SFTP Backup – TCP/22 | J20: Allow | K20: Gateway FW | L20: Outbound | M20: Explicit NSX Global Manager backup path to external SFTP per NSX LLD.

Sheet Route Table
A1: AES-220 | Route Table | Fleet ↔ Management Domain ↔ WLD ESXi
A2: Destination subnets auto-populated from ' IP Input Sheet'. Next-hop populated once IPs are entered.
A3: # | B3: Destination Network | C3: Subnet / IP | D3: Next Hop | E3: Via Interface | F3: Route Type | G3: Source Component | H3: AZ Scope | I3: Notes
A4: RT-01 | B4: Fleet Overlay Segment | C4: =IFERROR(IF('IP Input Sheet'!D11<>"",'IP Input Sheet'!D11,IF('IP Input Sheet'!E11<>"",'IP Input Sheet'!E11,'IP Input Sheet'!F11)),"[Enter IP]") | D4: T0 Gateway (per AZ) | E4: NSX Overlay | F4: Static/NSX | G4: All Fleet Components | H4: AZ1/2/3 | I4: NSX overlay depends on Edge/T0 health
A5: RT-02 | B5: VCF Ops Fleet Manager | C5: =IFERROR(IF('IP Input Sheet'!D5<>"",'IP Input Sheet'!D5,IF('IP Input Sheet'!E5<>"",'IP Input Sheet'!E5,'IP Input Sheet'!F5)),"[Enter IP]") | D5: T0 Gateway (per AZ) | E5: NSX Overlay | F5: NSX Overlay | G5: VCF Operations Fleet Manager | H5: AZ1/2/3 | I5: Fleet segment overlay routed
A6: RT-03 | B6: VCF Operations (VCFO) | C6: =IFERROR(IF('IP Input Sheet'!D6<>"",'IP Input Sheet'!D6,IF('IP Input Sheet'!E6<>"",'IP Input Sheet'!E6,'IP Input Sheet'!F6)),"[Enter IP]") | D6: T0 Gateway (per AZ) | E6: NSX Overlay | F6: NSX Overlay | G6: VCF Operations | H6: AZ1/2/3 | I6: Fleet segment
A7: RT-04 | B7: VCF Automation (VCFA) | C7: =IFERROR(IF('IP Input Sheet'!D7<>"",'IP Input Sheet'!D7,IF('IP Input Sheet'!E7<>"",'IP Input Sheet'!E7,'IP Input Sheet'!F7)),"[Enter IP]") | D7: T0 Gateway (per AZ) | E7: NSX Overlay | F7: NSX Overlay | G7: VCF Automation | H7: AZ1/2/3 | I7: Fleet segment
A8: RT-05 | B8: VCF Ops for Logs (VOL) | C8: =IFERROR(IF('IP Input Sheet'!D8<>"",'IP Input Sheet'!D8,IF('IP Input Sheet'!E8<>"",'IP Input Sheet'!E8,'IP Input Sheet'!F8)),"[Enter IP]") | D8: T0 Gateway (per AZ) | E8: NSX Overlay | F8: NSX Overlay | G8: VCF Operations for Logs | H8: AZ1/2/3 | I8: Fleet segment
A9: RT-06 | B9: VCF Ops for Networks (VON) | C9: =IFERROR(IF('IP Input Sheet'!D9<>"",'IP Input Sheet'!D9,IF('IP Input Sheet'!E9<>"",'IP Input Sheet'!E9,'IP Input Sheet'!F9)),"[Enter IP]") | D9: T0 Gateway (per AZ) | E9: NSX Overlay | F9: NSX Overlay | G9: VCF Ops for Networks | H9: AZ1/2/3 | I9: Fleet segment
A10: RT-07 | B10: Identity Broker (VIDB) | C10: =IFERROR(IF('IP Input Sheet'!D10<>"",'IP Input Sheet'!D10,IF('IP Input Sheet'!E10<>"",'IP Input Sheet'!E10,'IP Input Sheet'!F10)),"[Enter IP]") | D10: T0 Gateway (per AZ) | E10: NSX Overlay | F10: NSX Overlay | G10: Identity Broker | H10: AZ1/2/3 | I10: Fleet segment SSO critical path
A11: RT-08 | B11: VM Management (VLAN 2600) | C11: =IFERROR(IF('IP Input Sheet'!D13<>"",'IP Input Sheet'!D13,IF('IP Input Sheet'!E13<>"",'IP Input Sheet'!E13,'IP Input Sheet'!F13)),"[Enter IP]") | D11: ToR Switch (per AZ) | E11: VLAN 2600 | F11: VLAN/Static | G11: vCenter/NSX Mgr/SDDC Mgr | H11: AZ1/2/3 | I11: VLAN-backed direct physical, no NSX dependency
A12: RT-09 | B12: vCenter Server | C12: =IFERROR(IF('IP Input Sheet'!D13<>"",'IP Input Sheet'!D13,IF('IP Input Sheet'!E13<>"",'IP Input Sheet'!E13,'IP Input Sheet'!F13)),"[Enter IP]") | D12: ToR Switch (per AZ) | E12: VLAN 2600 | F12: Static | G12: vCenter Server | H12: AZ1/2/3
A13: RT-10 | B13: NSX Manager | C13: =IFERROR(IF('IP Input Sheet'!D14<>"",'IP Input Sheet'!D14,IF('IP Input Sheet'!E14<>"",'IP Input Sheet'!E14,'IP Input Sheet'!F14)),"[Enter IP]") | D13: ToR Switch (per AZ) | E13: VLAN 2600 | F13: Static | G13: NSX Manager | H13: AZ1/2/3
A14: RT-11 | B14: SDDC Manager | C14: =IFERROR(IF('IP Input Sheet'!D16<>"",'IP Input Sheet'!D16,IF('IP Input Sheet'!E16<>"",'IP Input Sheet'!E16,'IP Input Sheet'!F16)),"[Enter IP]") | D14: ToR Switch (per AZ) | E14: VLAN 2600 | F14: Static | G14: SDDC Manager | H14: AZ1/2/3
A15: RT-12 | B15: ESXi Mgmt — WLD | C15: =IFERROR(IF('IP Input Sheet'!D54<>"",'IP Input Sheet'!D54,IF('IP Input Sheet'!E54<>"",'IP Input Sheet'!E54,'IP Input Sheet'!F54)),"[Enter IP]") | D15: ToR Switch (per AZ) | E15: vDSW01 VM Mgmt PG | F15: Static | G15: ESXi Hosts WLD | H15: AZ1/2/3 | I15: WLD cluster hosts
A16: RT-13 | B16: ESXi Mgmt — Mgmt Domain | C16: =IFERROR(IF('IP Input Sheet'!D18<>"",'IP Input Sheet'!D18,IF('IP Input Sheet'!E18<>"",'IP Input Sheet'!E18,'IP Input Sheet'!F18)),"[Enter IP]") | D16: ToR Switch (per AZ) | E16: vDSM01 VM Mgmt PG | F16: Static | G16: ESXi Hosts Mgmt | H16: AZ1/2/3 | I16: Mgmt domain cluster hosts
A17: RT-14 | B17: Workload Ext Subnet | C17: =IFERROR(IF('IP Input Sheet'!D55<>"",'IP Input Sheet'!D55,IF('IP Input Sheet'!E55<>"",'IP Input Sheet'!E55,'IP Input Sheet'!F55)),"[Enter IP]") | D17: T0 Gateway (per AZ) | E17: NSX Edge / Uplink | F17: BGP Advertised | G17: Avi VIPs / WLD external | H17: AZ1/2/3 | I17: VIP subnet BGP advertised via Edge to ToR
A18: RT-15 | B18: DNS Server | C18: ='IP Input Sheet'!D60 | D18: Edge Node → ToR | E18: Uplink VLAN | F18: Static | G18: All components | H18: DC-wide | I18: Outbound via Edge N-S path
A19: RT-16 | B19: NTP Server | C19: ='IP Input Sheet'!D61 | D19: Edge Node → ToR | E19: Uplink VLAN | F19: Static | G19: All components | H19: DC-wide
A20: RT-17 | B20: AD/LDAP Server | C20: ='IP Input Sheet'!D62 | D20: Edge Node → ToR | E20: Uplink VLAN | F20: Static | G20: Fleet+Mgmt components | H20: DC-wide
A21: RT-18 | B21: CA Certificate Server | C21: ='IP Input Sheet'!D63 | D21: Edge Node → ToR | E21: Uplink VLAN | F21: Static | G21: Fleet+Mgmt components | H21: DC-wide
A22: RT-19 | B22: SFTP Backup Server | C22: ='IP Input Sheet'!D64 | D22: Edge Node → ToR | E22: Uplink VLAN | F22: Static | G22: SDDC Mgr / VCF Ops | H22: DC-wide
A23: RT-20 | B23: Host TEP Subnet | C23: [VLAN TBD] | D23: Physical Fabric | E23: Host TEP VLAN | F23: VLAN | G23: NSX Host TEP | H23: Per AZ | I23: GENEVE encap MTU must be 1600+
A24: RT-21 | B24: Edge TEP Subnet | C24: VLAN 2603 | D24: Physical Fabric | E24: Edge TEP VLAN | F24: VLAN | G24: NSX Edge TEP | H24: Per AZ | I24: Edge nodes GENEVE tunnels
A25: RT-22 | B25: Remote TEP Subnet | C25: VLAN 2605 | D25: Super Spine | E25: RTEP VLAN | F25: VLAN | G25: Cross-AZ tunnels | H25: DC-wide | I25: Cross-AZ NSX overlay RTEP
A26: RT-23 | B26: Super Spine | C26: [Physical] | D26: Physical Routing | E26: Uplink 2606/2607/2608/2609 | F26: BGP | G26: All AZs | H26: DC-wide | I26: BGP between Edge nodes and ToR switches
A27: RT-13 | B27: VCF OPS Network Collector (M7) | C27: =IFERROR(IF('IP Input Sheet'!D19<>"",'IP Input Sheet'!D19,IF('IP Input Sheet'!E19<>"",'IP Input Sheet'!E19,'IP Input Sheet'!F19)),"[Enter IP]") | D27: ToR Switch (per AZ) | E27: VLAN 2600 | F27: Static | G27: VCF OPS Network Collector | H27: AZ1/AZ2 | I27: M7 — Mgmt domain VLAN
A28: RT-14 | B28: NSX Edge Uplink — Rack1 VLAN 2606 | C28: ='IP Input Sheet'!D22 | D28: ToR Rack1 | E28: VLAN 2606 Uplink | F28: BGP Peer | G28: NSX Edge Node 1 | H28: Per AZ | I28: Edge→ToR BGP peering — same /30 subnet
A29: RT-15 | B29: NSX Edge Uplink — Rack1 VLAN 2607 | C29: ='IP Input Sheet'!D23 | D29: ToR Rack1 | E29: VLAN 2607 Uplink | F29: BGP Peer | G29: NSX Edge Node 2 | H29: Per AZ | I29: Edge→ToR BGP peering — same /30 subnet
A30: RT-16 | B30: NSX Edge Uplink — Rack2 VLAN 2608 | C30: ='IP Input Sheet'!D24 | D30: ToR Rack2 | E30: VLAN 2608 Uplink | F30: BGP Peer | G30: NSX Edge Node 1 | H30: Per AZ | I30: Edge→ToR BGP peering
A31: RT-17 | B31: NSX Edge Uplink — Rack2 VLAN 2609 | C31: ='IP Input Sheet'!D25 | D31: ToR Rack2 | E31: VLAN 2609 Uplink | F31: BGP Peer | G31: NSX Edge Node 2 | H31: Per AZ | I31: Edge→ToR BGP peering
A32: RT-18 | B32: Edge TEP Subnet (VLAN 2603) | C32: =IFERROR(IF('IP Input Sheet'!D30<>"",'IP Input Sheet'!D30,IF('IP Input Sheet'!E30<>"",'IP Input Sheet'!E30,'IP Input Sheet'!F30)),"[Enter IP]") | D32: Physical Fabric | E32: Edge TEP VLAN 2603 | F32: VLAN | G32: NSX Edge TEP | H32: Per AZ | I32: Intra-AZ HA + GENEVE — MTU 1600+
A33: RT-19 | B33: Remote TEP — Cross-AZ (VLAN 2605) | C33: =IFERROR(IF('IP Input Sheet'!D31<>"",'IP Input Sheet'!D31,IF('IP Input Sheet'!E31<>"",'IP Input Sheet'!E31,'IP Input Sheet'!F31)),"[Enter IP]") | D33: Super Spine | E33: RTEP VLAN 2605 | F33: VLAN | G33: Cross-AZ NSX Overlay | H33: DC-wide | I33: AZ1↔AZ2↔AZ3 GENEVE tunnels
A34: RT-20 | B34: ToR BGP Peer IPs | C34: =IFERROR(IF('IP Input Sheet'!D32<>"",'IP Input Sheet'!D32,IF('IP Input Sheet'!E32<>"",'IP Input Sheet'!E32,'IP Input Sheet'!F32)),"[Enter IP]") | D34: Physical ToR Switch | E34: Uplink SVIs | F34: BGP | G34: ToR Switch (Network Team) | H34: Per AZ | I34: Get from network team — not Raju
A35: RT-E1-EU1 | B35: Edge 1 EU1 (VLAN 2606 Rack 1) | C35: =IFERROR(IF('IP Input Sheet'!D21<>"",'IP Input Sheet'!D21,IF('IP Input Sheet'!E21<>"",'IP Input Sheet'!E21,'IP Input Sheet'!F21)),"[Enter IP]") | D35: ToR Rack 1 (EU11) | E35: VLAN 2606 SVI | F35: BGP Peer | G35: NSX Edge 1 | H35: Per AZ | I35: EU1↔EU11
A36: RT-E1-EU2 | B36: Edge 1 EU2 (VLAN 2607 Rack 1) | C36: =IFERROR(IF('IP Input Sheet'!D22<>"",'IP Input Sheet'!D22,IF('IP Input Sheet'!E22<>"",'IP Input Sheet'!E22,'IP Input Sheet'!F22)),"[Enter IP]") | D36: ToR Rack 1 (EU12) | E36: VLAN 2607 SVI | F36: BGP Peer | G36: NSX Edge 1 | H36: Per AZ | I36: EU2↔EU12
A37: RT-E2-EU3 | B37: Edge 2 EU3 (VLAN 2606 Rack 1) | C37: =IFERROR(IF('IP Input Sheet'!D23<>"",'IP Input Sheet'!D23,IF('IP Input Sheet'!E23<>"",'IP Input Sheet'!E23,'IP Input Sheet'!F23)),"[Enter IP]") | D37: ToR Rack 1 (EU11) | E37: VLAN 2606 SVI | F37: BGP Peer | G37: NSX Edge 2 | H37: Per AZ | I37: EU3↔EU11
A38: RT-E2-EU4 | B38: Edge 2 EU4 (VLAN 2607 Rack 1) | C38: =IFERROR(IF('IP Input Sheet'!D24<>"",'IP Input Sheet'!D24,IF('IP Input Sheet'!E24<>"",'IP Input Sheet'!E24,'IP Input Sheet'!F24)),"[Enter IP]") | D38: ToR Rack 1 (EU12) | E38: VLAN 2607 SVI | F38: BGP Peer | G38: NSX Edge 2 | H38: Per AZ | I38: EU4↔EU12
A39: RT-E3-EU5 | B39: Edge 3 EU5 (VLAN 2608 Rack 2) | C39: =IFERROR(IF('IP Input Sheet'!D25<>"",'IP Input Sheet'!D25,IF('IP Input Sheet'!E25<>"",'IP Input Sheet'!E25,'IP Input Sheet'!F25)),"[Enter IP]") | D39: ToR Rack 2 (EU13) | E39: VLAN 2608 SVI | F39: BGP Peer | G39: NSX Edge 3 | H39: Per AZ | I39: EU5↔EU13
A40: RT-E3-EU6 | B40: Edge 3 EU6 (VLAN 2609 Rack 2) | C40: =IFERROR(IF('IP Input Sheet'!D26<>"",'IP Input Sheet'!D26,IF('IP Input Sheet'!E26<>"",'IP Input Sheet'!E26,'IP Input Sheet'!F26)),"[Enter IP]") | D40: ToR Rack 2 (EU14) | E40: VLAN 2609 SVI | F40: BGP Peer | G40: NSX Edge 3 | H40: Per AZ | I40: EU6↔EU14
...

Sheet Port Summary
A1: AES-220 | Unique Port Reference | All Fleet Firewall Ports Consolidated
A2: Port | B2: Protocol | C2: Service | D2: Used By (Source) | E2: Used By (Destination) | F2: Notes
A3: 22 | B3: TCP | C3: SSH | D3: VCF Installer, SDDC Mgr, Fleet Mgr, VCFA, VCFO | E3: ESXi, SDDC Mgr, Fleet VMs, SFTP | F3: Admin only restrict to jump host / bastion
A4: 50 | B4: ESP | C4: Encapsulating Security Payload | D4: Identity Broker | E4: ALL | F4: Used by k8s to encapsulate hidden networks — bidirectional
A5: 53 | B5: TCP/UDP | C5: DNS | D5: All Fleet + VCF Components | E5: DNS Servers | F5: Bidirectional ALL Fleet-level and VCF instance-level
A6: 123 | B6: UDP | C6: NTP | D6: All Fleet + VCF Components | E6: NTP Servers | F6: Time sync ALL VCF 9 components
A7: 161 | B7: TCP | C7: SNMP | D7: VCF Ops for Networks (VON) | E7: Switches/Routers | F7: SNMP polling physical devices
A8: 389 | B8: TCP/UDP | C8: LDAP | D8: VCF Ops, Identity Broker, vCenter | E8: AD/LDAP Servers | F8: Directory lookups Active Directory integration
A9: 443 | B9: TCP | C9: HTTPS | D9: All Fleet + Mgmt Components | E9: All Fleet + Mgmt Components | F9: Primary management port — all component comms incl. VLR SSO registration + site pair
A10: 514 | B10: TCP/UDP | C10: Syslog | D10: vCenter, NSX, SDDC, ESXi, VCFA | E10: VCF Ops for Logs (VOL) | F10: Remote syslog all components log to VOL
A11: 636 | B11: TCP | C11: LDAPS | D11: VCF Ops, Identity Broker, vCenter | E11: AD/LDAP Servers | F11: Secure LDAP
A12: 902 | B12: TCP | C12: Heartbeat / VMRC | D12: vCenter, VCF Automation, VMware Live Recovery (VLR) | E12: ESXi Hosts | F12: Core mgmt comms vCenter↔ESXi + VM console + VLR VMkernel heartbeat
A13: 1514 | B13: TCP | C13: Syslog over TLS | D13: vCenter, NSX, ESXi, VCFA | E13: VCF Ops for Logs (VOL) | F13: Secure syslog TLS
... A46: 44046 | B46: TCP | C46: vSphere Replication NFC — Alternate | D46: VMware Live Recovery (VLR) | E46: ESXi Hosts (Mgmt Domain) | F46: CF row 165-175 — Alternate NFC port for vSphere Replication. Bidirectional.
